[16/Jul/2015 10:01:56] WARNING [django.request:170] Not Found: /apple-touch-icon-precomposed.png
[16/Jul/2015 10:01:56] WARNING [django.request:170] Not Found: /apple-touch-icon.png
[16/Jul/2015 10:02:27] ERROR [django.request:256] Internal Server Error: /open/filter/
Traceback (most recent call last):
  File "/Users/hanschristiangregersen/.virtualenvs/booked/lib/python3.4/site-packages/django/db/backends/utils.py", line 64, in execute
    return self.cursor.execute(sql, params)
  File "/Users/hanschristiangregersen/.virtualenvs/booked/lib/python3.4/site-packages/django/db/backends/sqlite3/base.py", line 318, in execute
    return Database.Cursor.execute(self, query, params)
sqlite3.OperationalError: no such table: pc_computer_labs

The above exception was the direct cause of the following exception:

Traceback (most recent call last):
  File "/Users/hanschristiangregersen/.virtualenvs/booked/lib/python3.4/site-packages/django/core/handlers/base.py", line 132, in get_response
    response = wrapped_callback(request, *callback_args, **callback_kwargs)
  File "/Users/hanschristiangregersen/PycharmProjects/InternProject/pc/views.py", line 57, in filter_suggestions
    data = sorted(data, key=lambda x: x.get_distance(long1=usr_longitude, lat1=usr_latitude))
  File "/Users/hanschristiangregersen/.virtualenvs/booked/lib/python3.4/site-packages/django/db/models/query.py", line 162, in __iter__
    self._fetch_all()
  File "/Users/hanschristiangregersen/.virtualenvs/booked/lib/python3.4/site-packages/django/db/models/query.py", line 965, in _fetch_all
    self._result_cache = list(self.iterator())
  File "/Users/hanschristiangregersen/.virtualenvs/booked/lib/python3.4/site-packages/django/db/models/query.py", line 238, in iterator
    results = compiler.execute_sql()
  File "/Users/hanschristiangregersen/.virtualenvs/booked/lib/python3.4/site-packages/django/db/models/sql/compiler.py", line 840, in execute_sql
    cursor.execute(sql, params)
  File "/Users/hanschristiangregersen/.virtualenvs/booked/lib/python3.4/site-packages/django/db/backends/utils.py", line 79, in execute
    return super(CursorDebugWrapper, self).execute(sql, params)
  File "/Users/hanschristiangregersen/.virtualenvs/booked/lib/python3.4/site-packages/django/db/backends/utils.py", line 64, in execute
    return self.cursor.execute(sql, params)
  File "/Users/hanschristiangregersen/.virtualenvs/booked/lib/python3.4/site-packages/django/db/utils.py", line 97, in __exit__
    six.reraise(dj_exc_type, dj_exc_value, traceback)
  File "/Users/hanschristiangregersen/.virtualenvs/booked/lib/python3.4/site-packages/django/utils/six.py", line 658, in reraise
    raise value.with_traceback(tb)
  File "/Users/hanschristiangregersen/.virtualenvs/booked/lib/python3.4/site-packages/django/db/backends/utils.py", line 64, in execute
    return self.cursor.execute(sql, params)
  File "/Users/hanschristiangregersen/.virtualenvs/booked/lib/python3.4/site-packages/django/db/backends/sqlite3/base.py", line 318, in execute
    return Database.Cursor.execute(self, query, params)
django.db.utils.OperationalError: no such table: pc_computer_labs
[20/Jul/2015 08:55:23] ERROR [django.request:256] Internal Server Error: /like/
Traceback (most recent call last):
  File "/Users/hanschristiangregersen/.virtualenvs/booked/lib/python3.4/site-packages/django/core/handlers/base.py", line 132, in get_response
    response = wrapped_callback(request, *callback_args, **callback_kwargs)
  File "/Users/hanschristiangregersen/PycharmProjects/InternProject/users/views.py", line 130, in like
    user.pc_favourites.get(id=pc_id)
  File "/Users/hanschristiangregersen/.virtualenvs/booked/lib/python3.4/site-packages/django/utils/functional.py", line 227, in inner
    return func(self._wrapped, *args)
AttributeError: 'AnonymousUser' object has no attribute 'pc_favourites'
[20/Jul/2015 08:55:23] ERROR [django.request:256] Internal Server Error: /like/
Traceback (most recent call last):
  File "/Users/hanschristiangregersen/.virtualenvs/booked/lib/python3.4/site-packages/django/core/handlers/base.py", line 132, in get_response
    response = wrapped_callback(request, *callback_args, **callback_kwargs)
  File "/Users/hanschristiangregersen/PycharmProjects/InternProject/users/views.py", line 130, in like
    user.pc_favourites.get(id=pc_id)
  File "/Users/hanschristiangregersen/.virtualenvs/booked/lib/python3.4/site-packages/django/utils/functional.py", line 227, in inner
    return func(self._wrapped, *args)
AttributeError: 'AnonymousUser' object has no attribute 'pc_favourites'
[20/Jul/2015 08:55:24] ERROR [django.request:256] Internal Server Error: /like/
Traceback (most recent call last):
  File "/Users/hanschristiangregersen/.virtualenvs/booked/lib/python3.4/site-packages/django/core/handlers/base.py", line 132, in get_response
    response = wrapped_callback(request, *callback_args, **callback_kwargs)
  File "/Users/hanschristiangregersen/PycharmProjects/InternProject/users/views.py", line 130, in like
    user.pc_favourites.get(id=pc_id)
  File "/Users/hanschristiangregersen/.virtualenvs/booked/lib/python3.4/site-packages/django/utils/functional.py", line 227, in inner
    return func(self._wrapped, *args)
AttributeError: 'AnonymousUser' object has no attribute 'pc_favourites'
[20/Jul/2015 08:55:24] ERROR [django.request:256] Internal Server Error: /like/
Traceback (most recent call last):
  File "/Users/hanschristiangregersen/.virtualenvs/booked/lib/python3.4/site-packages/django/core/handlers/base.py", line 132, in get_response
    response = wrapped_callback(request, *callback_args, **callback_kwargs)
  File "/Users/hanschristiangregersen/PycharmProjects/InternProject/users/views.py", line 130, in like
    user.pc_favourites.get(id=pc_id)
  File "/Users/hanschristiangregersen/.virtualenvs/booked/lib/python3.4/site-packages/django/utils/functional.py", line 227, in inner
    return func(self._wrapped, *args)
AttributeError: 'AnonymousUser' object has no attribute 'pc_favourites'
[20/Jul/2015 08:55:24] ERROR [django.request:256] Internal Server Error: /like/
Traceback (most recent call last):
  File "/Users/hanschristiangregersen/.virtualenvs/booked/lib/python3.4/site-packages/django/core/handlers/base.py", line 132, in get_response
    response = wrapped_callback(request, *callback_args, **callback_kwargs)
  File "/Users/hanschristiangregersen/PycharmProjects/InternProject/users/views.py", line 130, in like
    user.pc_favourites.get(id=pc_id)
  File "/Users/hanschristiangregersen/.virtualenvs/booked/lib/python3.4/site-packages/django/utils/functional.py", line 227, in inner
    return func(self._wrapped, *args)
AttributeError: 'AnonymousUser' object has no attribute 'pc_favourites'
[20/Jul/2015 08:55:24] ERROR [django.request:256] Internal Server Error: /like/
Traceback (most recent call last):
  File "/Users/hanschristiangregersen/.virtualenvs/booked/lib/python3.4/site-packages/django/core/handlers/base.py", line 132, in get_response
    response = wrapped_callback(request, *callback_args, **callback_kwargs)
  File "/Users/hanschristiangregersen/PycharmProjects/InternProject/users/views.py", line 130, in like
    user.pc_favourites.get(id=pc_id)
  File "/Users/hanschristiangregersen/.virtualenvs/booked/lib/python3.4/site-packages/django/utils/functional.py", line 227, in inner
    return func(self._wrapped, *args)
AttributeError: 'AnonymousUser' object has no attribute 'pc_favourites'
[20/Jul/2015 10:34:05] WARNING [django.request:170] Not Found: /apple-touch-icon-precomposed.png
[20/Jul/2015 10:34:05] WARNING [django.request:170] Not Found: /apple-touch-icon.png
[20/Jul/2015 15:28:34] ERROR [django.request:256] Internal Server Error: /bookable/filter/
Traceback (most recent call last):
  File "/Users/hanschristiangregersen/.virtualenvs/booked/lib/python3.4/site-packages/django/core/handlers/base.py", line 132, in get_response
    response = wrapped_callback(request, *callback_args, **callback_kwargs)
  File "/Users/hanschristiangregersen/PycharmProjects/InternProject/rooms/views.py", line 121, in filter_suggestions
    data = data.filter(abbreviation=request.GET['building'])
AttributeError: 'list' object has no attribute 'filter'
[21/Jul/2015 14:01:31] ERROR [django.request:256] Internal Server Error: /like/
Traceback (most recent call last):
  File "/Users/hanschristiangregersen/.virtualenvs/booked/lib/python3.4/site-packages/django/core/handlers/base.py", line 132, in get_response
    response = wrapped_callback(request, *callback_args, **callback_kwargs)
  File "/Users/hanschristiangregersen/PycharmProjects/InternProject/users/views.py", line 130, in like
    user.pc_favourites.get(id=pc_id)
  File "/Users/hanschristiangregersen/.virtualenvs/booked/lib/python3.4/site-packages/django/utils/functional.py", line 227, in inner
    return func(self._wrapped, *args)
AttributeError: 'AnonymousUser' object has no attribute 'pc_favourites'
[21/Jul/2015 14:01:43] ERROR [django.request:256] Internal Server Error: /like/
Traceback (most recent call last):
  File "/Users/hanschristiangregersen/.virtualenvs/booked/lib/python3.4/site-packages/django/core/handlers/base.py", line 132, in get_response
    response = wrapped_callback(request, *callback_args, **callback_kwargs)
  File "/Users/hanschristiangregersen/PycharmProjects/InternProject/users/views.py", line 130, in like
    user.pc_favourites.get(id=pc_id)
  File "/Users/hanschristiangregersen/.virtualenvs/booked/lib/python3.4/site-packages/django/utils/functional.py", line 227, in inner
    return func(self._wrapped, *args)
AttributeError: 'AnonymousUser' object has no attribute 'pc_favourites'
[21/Jul/2015 14:32:56] ERROR [django.request:256] Internal Server Error: /open/filter/
Traceback (most recent call last):
  File "/Users/hanschristiangregersen/.virtualenvs/booked/lib/python3.4/site-packages/django/core/handlers/base.py", line 132, in get_response
    response = wrapped_callback(request, *callback_args, **callback_kwargs)
  File "/Users/hanschristiangregersen/PycharmProjects/InternProject/pc/views.py", line 51, in filter_suggestions
    building_details=data)
  File "/Users/hanschristiangregersen/PycharmProjects/InternProject/core/utilities.py", line 122, in sortByDistance
    building_details = sorted(building_details, key=lambda x: get_distance(
  File "/Users/hanschristiangregersen/PycharmProjects/InternProject/core/utilities.py", line 123, in <lambda>
    x['longitude'], x['latitude'], long1=usr_longitude, lat1=usr_latitude))
TypeError: 'Computer_Labs' object is not subscriptable
[21/Jul/2015 14:44:01] ERROR [django.request:256] Internal Server Error: /open/filter/
Traceback (most recent call last):
  File "/Users/hanschristiangregersen/.virtualenvs/booked/lib/python3.4/site-packages/django/core/handlers/base.py", line 132, in get_response
    response = wrapped_callback(request, *callback_args, **callback_kwargs)
  File "/Users/hanschristiangregersen/PycharmProjects/InternProject/pc/views.py", line 60, in filter_suggestions
    usr_latitude=usr_latitude)
  File "/Users/hanschristiangregersen/PycharmProjects/InternProject/core/utilities.py", line 156, in sortingByLocationAndEmptiness
    average_distance = average_distance + pc_lab.get_distance(long1=usr_longitude, lat1=usr_latitude)
AttributeError: 'Computer_Labs' object has no attribute 'get_distance'
[21/Jul/2015 14:59:25] ERROR [django.request:256] Internal Server Error: /open/filter/
Traceback (most recent call last):
  File "/Users/hanschristiangregersen/.virtualenvs/booked/lib/python3.4/site-packages/django/core/handlers/base.py", line 132, in get_response
    response = wrapped_callback(request, *callback_args, **callback_kwargs)
  File "/Users/hanschristiangregersen/PycharmProjects/InternProject/pc/views.py", line 60, in filter_suggestions
    usr_latitude=usr_latitude)
  File "/Users/hanschristiangregersen/PycharmProjects/InternProject/core/utilities.py", line 173, in sortingByLocationAndEmptiness
    key=lambda x: x.get_heuristic(average_distance, average_ratio, sd_distance, sd_ratio,
  File "/Users/hanschristiangregersen/PycharmProjects/InternProject/core/utilities.py", line 174, in <lambda>
    usr_longitude, usr_latitude))
  File "/Users/hanschristiangregersen/PycharmProjects/InternProject/pc/models.py", line 82, in get_heuristic
    normalised_distance = (self.get_distance(long, lat) - average_distance) / standard_deviation_distance
AttributeError: 'Computer_Labs' object has no attribute 'get_distance'
[21/Jul/2015 15:00:19] ERROR [django.request:256] Internal Server Error: /open/filter/
Traceback (most recent call last):
  File "/Users/hanschristiangregersen/.virtualenvs/booked/lib/python3.4/site-packages/django/core/handlers/base.py", line 132, in get_response
    response = wrapped_callback(request, *callback_args, **callback_kwargs)
  File "/Users/hanschristiangregersen/PycharmProjects/InternProject/pc/views.py", line 60, in filter_suggestions
    usr_latitude=usr_latitude)
  File "/Users/hanschristiangregersen/PycharmProjects/InternProject/core/utilities.py", line 173, in sortingByLocationAndEmptiness
    key=lambda x: x.get_heuristic(average_distance, average_ratio, sd_distance, sd_ratio,
TypeError: unorderable types: complex() < complex()
[22/Jul/2015 10:37:57] ERROR [django.request:256] Internal Server Error: /
Traceback (most recent call last):
  File "C:\Python34\lib\site-packages\django\core\urlresolvers.py", line 394, in urlconf_module
    return self._urlconf_module
AttributeError: 'RegexURLResolver' object has no attribute '_urlconf_module'

During handling of the above exception, another exception occurred:

Traceback (most recent call last):
  File "C:\Python34\lib\site-packages\django\core\handlers\base.py", line 119, in get_response
    resolver_match = resolver.resolve(request.path_info)
  File "C:\Python34\lib\site-packages\django\core\urlresolvers.py", line 366, in resolve
    for pattern in self.url_patterns:
  File "C:\Python34\lib\site-packages\django\core\urlresolvers.py", line 402, in url_patterns
    patterns = getattr(self.urlconf_module, "urlpatterns", self.urlconf_module)
  File "C:\Python34\lib\site-packages\django\core\urlresolvers.py", line 396, in urlconf_module
    self._urlconf_module = import_module(self.urlconf_name)
  File "C:\Python34\lib\importlib\__init__.py", line 109, in import_module
    return _bootstrap._gcd_import(name[level:], package, level)
  File "<frozen importlib._bootstrap>", line 2254, in _gcd_import
  File "<frozen importlib._bootstrap>", line 2237, in _find_and_load
  File "<frozen importlib._bootstrap>", line 2226, in _find_and_load_unlocked
  File "<frozen importlib._bootstrap>", line 1200, in _load_unlocked
  File "<frozen importlib._bootstrap>", line 1129, in _exec
  File "<frozen importlib._bootstrap>", line 1471, in exec_module
  File "<frozen importlib._bootstrap>", line 321, in _call_with_frames_removed
  File "C:\Users\s1337523\Local Documents\MyEdProject\core\urls.py", line 25, in <module>
    url(r'^api/', include('api.urls')),
  File "C:\Python34\lib\site-packages\django\conf\urls\__init__.py", line 33, in include
    urlconf_module = import_module(urlconf_module)
  File "C:\Python34\lib\importlib\__init__.py", line 109, in import_module
    return _bootstrap._gcd_import(name[level:], package, level)
  File "<frozen importlib._bootstrap>", line 2254, in _gcd_import
  File "<frozen importlib._bootstrap>", line 2237, in _find_and_load
  File "<frozen importlib._bootstrap>", line 2212, in _find_and_load_unlocked
  File "<frozen importlib._bootstrap>", line 321, in _call_with_frames_removed
  File "<frozen importlib._bootstrap>", line 2254, in _gcd_import
  File "<frozen importlib._bootstrap>", line 2237, in _find_and_load
  File "<frozen importlib._bootstrap>", line 2224, in _find_and_load_unlocked
ImportError: No module named 'api'
[22/Jul/2015 10:38:10] ERROR [django.request:256] Internal Server Error: /
Traceback (most recent call last):
  File "C:\Python34\lib\site-packages\django\core\handlers\base.py", line 132, in get_response
    response = wrapped_callback(request, *callback_args, **callback_kwargs)
  File "C:\Users\s1337523\Local Documents\MyEdProject\users\views.py", line 27, in index
    return render(request, 'users/index.html')
  File "C:\Python34\lib\site-packages\django\shortcuts.py", line 67, in render
    template_name, context, request=request, using=using)
  File "C:\Python34\lib\site-packages\django\template\loader.py", line 98, in render_to_string
    template = get_template(template_name, using=using)
  File "C:\Python34\lib\site-packages\django\template\loader.py", line 46, in get_template
    raise TemplateDoesNotExist(template_name)
django.template.base.TemplateDoesNotExist: users/index.html
[22/Jul/2015 10:39:44] WARNING [django.request:170] Not Found: /'history
[22/Jul/2015 10:39:50] WARNING [django.request:170] Not Found: /'history
[22/Jul/2015 10:43:03] ERROR [django.request:256] Internal Server Error: /history/
Traceback (most recent call last):
  File "C:\Python34\lib\site-packages\django\core\urlresolvers.py", line 120, in get_callable
    view_func = getattr(mod, func_name)
AttributeError: 'module' object has no attribute 'history'

During handling of the above exception, another exception occurred:

Traceback (most recent call last):
  File "C:\Python34\lib\site-packages\django\core\handlers\base.py", line 119, in get_response
    resolver_match = resolver.resolve(request.path_info)
  File "C:\Python34\lib\site-packages\django\core\urlresolvers.py", line 368, in resolve
    sub_match = pattern.resolve(new_path)
  File "C:\Python34\lib\site-packages\django\core\urlresolvers.py", line 240, in resolve
    return ResolverMatch(self.callback, args, kwargs, self.name)
  File "C:\Python34\lib\site-packages\django\core\urlresolvers.py", line 247, in callback
    self._callback = get_callable(self._callback_str)
  File "C:\Python34\lib\functools.py", line 448, in wrapper
    result = user_function(*args, **kwds)
  File "C:\Python34\lib\site-packages\django\core\urlresolvers.py", line 127, in get_callable
    (lookup_view, mod_name))
django.core.exceptions.ViewDoesNotExist: Could not import 'users.views.history'. View does not exist in module users.views.
[22/Jul/2015 10:43:21] WARNING [django.request:170] Not Found: /'history
[22/Jul/2015 10:43:38] WARNING [django.request:170] Not Found: /'history
[22/Jul/2015 10:43:42] WARNING [django.request:170] Not Found: /'history
[22/Jul/2015 10:50:12] ERROR [django.request:256] Internal Server Error: /
Traceback (most recent call last):
  File "C:\Python34\lib\site-packages\django\core\urlresolvers.py", line 394, in urlconf_module
    return self._urlconf_module
AttributeError: 'RegexURLResolver' object has no attribute '_urlconf_module'

During handling of the above exception, another exception occurred:

Traceback (most recent call last):
  File "C:\Python34\lib\site-packages\django\core\handlers\base.py", line 119, in get_response
    resolver_match = resolver.resolve(request.path_info)
  File "C:\Python34\lib\site-packages\django\core\urlresolvers.py", line 366, in resolve
    for pattern in self.url_patterns:
  File "C:\Python34\lib\site-packages\django\core\urlresolvers.py", line 402, in url_patterns
    patterns = getattr(self.urlconf_module, "urlpatterns", self.urlconf_module)
  File "C:\Python34\lib\site-packages\django\core\urlresolvers.py", line 396, in urlconf_module
    self._urlconf_module = import_module(self.urlconf_name)
  File "C:\Python34\lib\importlib\__init__.py", line 109, in import_module
    return _bootstrap._gcd_import(name[level:], package, level)
  File "<frozen importlib._bootstrap>", line 2254, in _gcd_import
  File "<frozen importlib._bootstrap>", line 2237, in _find_and_load
  File "<frozen importlib._bootstrap>", line 2226, in _find_and_load_unlocked
  File "<frozen importlib._bootstrap>", line 1200, in _load_unlocked
  File "<frozen importlib._bootstrap>", line 1129, in _exec
  File "<frozen importlib._bootstrap>", line 1471, in exec_module
  File "<frozen importlib._bootstrap>", line 321, in _call_with_frames_removed
  File "C:\Users\s1337523\Local Documents\MyEdProject\core\urls.py", line 36, in <module>
    url(r'',include('new.urls'))
  File "C:\Python34\lib\site-packages\django\conf\urls\__init__.py", line 33, in include
    urlconf_module = import_module(urlconf_module)
  File "C:\Python34\lib\importlib\__init__.py", line 109, in import_module
    return _bootstrap._gcd_import(name[level:], package, level)
  File "<frozen importlib._bootstrap>", line 2254, in _gcd_import
  File "<frozen importlib._bootstrap>", line 2237, in _find_and_load
  File "<frozen importlib._bootstrap>", line 2212, in _find_and_load_unlocked
  File "<frozen importlib._bootstrap>", line 321, in _call_with_frames_removed
  File "<frozen importlib._bootstrap>", line 2254, in _gcd_import
  File "<frozen importlib._bootstrap>", line 2237, in _find_and_load
  File "<frozen importlib._bootstrap>", line 2224, in _find_and_load_unlocked
ImportError: No module named 'new'
[22/Jul/2015 10:50:47] WARNING [django.request:170] Not Found: /labs/
[22/Jul/2015 10:51:14] ERROR [django.request:256] Internal Server Error: /history/
Traceback (most recent call last):
  File "C:\Python34\lib\site-packages\django\template\defaulttags.py", line 501, in render
    current_app=current_app)
  File "C:\Python34\lib\site-packages\django\core\urlresolvers.py", line 579, in reverse
    return force_text(iri_to_uri(resolver._reverse_with_prefix(view, prefix, *args, **kwargs)))
  File "C:\Python34\lib\site-packages\django\core\urlresolvers.py", line 496, in _reverse_with_prefix
    (lookup_view_s, args, kwargs, len(patterns), patterns))
django.core.urlresolvers.NoReverseMatch: Reverse for 'core.labs' with arguments '()' and keyword arguments '{}' not found. 0 pattern(s) tried: []

During handling of the above exception, another exception occurred:

Traceback (most recent call last):
  File "C:\Python34\lib\site-packages\django\core\handlers\base.py", line 132, in get_response
    response = wrapped_callback(request, *callback_args, **callback_kwargs)
  File "C:\Python34\lib\site-packages\django\contrib\auth\decorators.py", line 22, in _wrapped_view
    return view_func(request, *args, **kwargs)
  File "C:\Users\s1337523\Local Documents\MyEdProject\users\views.py", line 174, in history
    return render(request, 'users/history.html', context)
  File "C:\Python34\lib\site-packages\django\shortcuts.py", line 67, in render
    template_name, context, request=request, using=using)
  File "C:\Python34\lib\site-packages\django\template\loader.py", line 99, in render_to_string
    return template.render(context, request)
  File "C:\Python34\lib\site-packages\django\template\backends\django.py", line 74, in render
    return self.template.render(context)
  File "C:\Python34\lib\site-packages\django\template\base.py", line 209, in render
    return self._render(context)
  File "C:\Python34\lib\site-packages\django\template\base.py", line 201, in _render
    return self.nodelist.render(context)
  File "C:\Python34\lib\site-packages\django\template\base.py", line 903, in render
    bit = self.render_node(node, context)
  File "C:\Python34\lib\site-packages\django\template\debug.py", line 79, in render_node
    return node.render(context)
  File "C:\Python34\lib\site-packages\django\template\loader_tags.py", line 135, in render
    return compiled_parent._render(context)
  File "C:\Python34\lib\site-packages\django\template\base.py", line 201, in _render
    return self.nodelist.render(context)
  File "C:\Python34\lib\site-packages\django\template\base.py", line 903, in render
    bit = self.render_node(node, context)
  File "C:\Python34\lib\site-packages\django\template\debug.py", line 79, in render_node
    return node.render(context)
  File "C:\Python34\lib\site-packages\django\template\loader_tags.py", line 65, in render
    result = block.nodelist.render(context)
  File "C:\Python34\lib\site-packages\django\template\base.py", line 903, in render
    bit = self.render_node(node, context)
  File "C:\Python34\lib\site-packages\django\template\debug.py", line 79, in render_node
    return node.render(context)
  File "C:\Python34\lib\site-packages\django\template\defaulttags.py", line 507, in render
    six.reraise(*exc_info)
  File "C:\Python34\lib\site-packages\django\utils\six.py", line 659, in reraise
    raise value
  File "C:\Python34\lib\site-packages\django\template\defaulttags.py", line 493, in render
    url = reverse(view_name, args=args, kwargs=kwargs, current_app=current_app)
  File "C:\Python34\lib\site-packages\django\core\urlresolvers.py", line 579, in reverse
    return force_text(iri_to_uri(resolver._reverse_with_prefix(view, prefix, *args, **kwargs)))
  File "C:\Python34\lib\site-packages\django\core\urlresolvers.py", line 496, in _reverse_with_prefix
    (lookup_view_s, args, kwargs, len(patterns), patterns))
django.core.urlresolvers.NoReverseMatch: Reverse for 'labs' with arguments '()' and keyword arguments '{}' not found. 0 pattern(s) tried: []
[22/Jul/2015 10:52:08] ERROR [django.request:256] Internal Server Error: /history/
Traceback (most recent call last):
  File "C:\Python34\lib\site-packages\django\template\defaulttags.py", line 501, in render
    current_app=current_app)
  File "C:\Python34\lib\site-packages\django\core\urlresolvers.py", line 579, in reverse
    return force_text(iri_to_uri(resolver._reverse_with_prefix(view, prefix, *args, **kwargs)))
  File "C:\Python34\lib\site-packages\django\core\urlresolvers.py", line 496, in _reverse_with_prefix
    (lookup_view_s, args, kwargs, len(patterns), patterns))
django.core.urlresolvers.NoReverseMatch: Reverse for 'core.home' with arguments '()' and keyword arguments '{}' not found. 0 pattern(s) tried: []

During handling of the above exception, another exception occurred:

Traceback (most recent call last):
  File "C:\Python34\lib\site-packages\django\core\handlers\base.py", line 132, in get_response
    response = wrapped_callback(request, *callback_args, **callback_kwargs)
  File "C:\Python34\lib\site-packages\django\contrib\auth\decorators.py", line 22, in _wrapped_view
    return view_func(request, *args, **kwargs)
  File "C:\Users\s1337523\Local Documents\MyEdProject\users\views.py", line 174, in history
    return render(request, 'users/history.html', context)
  File "C:\Python34\lib\site-packages\django\shortcuts.py", line 67, in render
    template_name, context, request=request, using=using)
  File "C:\Python34\lib\site-packages\django\template\loader.py", line 99, in render_to_string
    return template.render(context, request)
  File "C:\Python34\lib\site-packages\django\template\backends\django.py", line 74, in render
    return self.template.render(context)
  File "C:\Python34\lib\site-packages\django\template\base.py", line 209, in render
    return self._render(context)
  File "C:\Python34\lib\site-packages\django\template\base.py", line 201, in _render
    return self.nodelist.render(context)
  File "C:\Python34\lib\site-packages\django\template\base.py", line 903, in render
    bit = self.render_node(node, context)
  File "C:\Python34\lib\site-packages\django\template\debug.py", line 79, in render_node
    return node.render(context)
  File "C:\Python34\lib\site-packages\django\template\loader_tags.py", line 135, in render
    return compiled_parent._render(context)
  File "C:\Python34\lib\site-packages\django\template\base.py", line 201, in _render
    return self.nodelist.render(context)
  File "C:\Python34\lib\site-packages\django\template\base.py", line 903, in render
    bit = self.render_node(node, context)
  File "C:\Python34\lib\site-packages\django\template\debug.py", line 79, in render_node
    return node.render(context)
  File "C:\Python34\lib\site-packages\django\template\loader_tags.py", line 65, in render
    result = block.nodelist.render(context)
  File "C:\Python34\lib\site-packages\django\template\base.py", line 903, in render
    bit = self.render_node(node, context)
  File "C:\Python34\lib\site-packages\django\template\debug.py", line 79, in render_node
    return node.render(context)
  File "C:\Python34\lib\site-packages\django\template\defaulttags.py", line 507, in render
    six.reraise(*exc_info)
  File "C:\Python34\lib\site-packages\django\utils\six.py", line 659, in reraise
    raise value
  File "C:\Python34\lib\site-packages\django\template\defaulttags.py", line 493, in render
    url = reverse(view_name, args=args, kwargs=kwargs, current_app=current_app)
  File "C:\Python34\lib\site-packages\django\core\urlresolvers.py", line 579, in reverse
    return force_text(iri_to_uri(resolver._reverse_with_prefix(view, prefix, *args, **kwargs)))
  File "C:\Python34\lib\site-packages\django\core\urlresolvers.py", line 496, in _reverse_with_prefix
    (lookup_view_s, args, kwargs, len(patterns), patterns))
django.core.urlresolvers.NoReverseMatch: Reverse for 'home' with arguments '()' and keyword arguments '{}' not found. 0 pattern(s) tried: []
[22/Jul/2015 10:54:39] ERROR [django.request:256] Internal Server Error: /history/
Traceback (most recent call last):
  File "C:\Python34\lib\site-packages\django\template\defaulttags.py", line 501, in render
    current_app=current_app)
  File "C:\Python34\lib\site-packages\django\core\urlresolvers.py", line 579, in reverse
    return force_text(iri_to_uri(resolver._reverse_with_prefix(view, prefix, *args, **kwargs)))
  File "C:\Python34\lib\site-packages\django\core\urlresolvers.py", line 496, in _reverse_with_prefix
    (lookup_view_s, args, kwargs, len(patterns), patterns))
django.core.urlresolvers.NoReverseMatch: Reverse for 'core.labs' with arguments '()' and keyword arguments '{}' not found. 0 pattern(s) tried: []

During handling of the above exception, another exception occurred:

Traceback (most recent call last):
  File "C:\Python34\lib\site-packages\django\core\handlers\base.py", line 132, in get_response
    response = wrapped_callback(request, *callback_args, **callback_kwargs)
  File "C:\Python34\lib\site-packages\django\contrib\auth\decorators.py", line 22, in _wrapped_view
    return view_func(request, *args, **kwargs)
  File "C:\Users\s1337523\Local Documents\MyEdProject\users\views.py", line 174, in history
    return render(request, 'users/history.html', context)
  File "C:\Python34\lib\site-packages\django\shortcuts.py", line 67, in render
    template_name, context, request=request, using=using)
  File "C:\Python34\lib\site-packages\django\template\loader.py", line 99, in render_to_string
    return template.render(context, request)
  File "C:\Python34\lib\site-packages\django\template\backends\django.py", line 74, in render
    return self.template.render(context)
  File "C:\Python34\lib\site-packages\django\template\base.py", line 209, in render
    return self._render(context)
  File "C:\Python34\lib\site-packages\django\template\base.py", line 201, in _render
    return self.nodelist.render(context)
  File "C:\Python34\lib\site-packages\django\template\base.py", line 903, in render
    bit = self.render_node(node, context)
  File "C:\Python34\lib\site-packages\django\template\debug.py", line 79, in render_node
    return node.render(context)
  File "C:\Python34\lib\site-packages\django\template\loader_tags.py", line 135, in render
    return compiled_parent._render(context)
  File "C:\Python34\lib\site-packages\django\template\base.py", line 201, in _render
    return self.nodelist.render(context)
  File "C:\Python34\lib\site-packages\django\template\base.py", line 903, in render
    bit = self.render_node(node, context)
  File "C:\Python34\lib\site-packages\django\template\debug.py", line 79, in render_node
    return node.render(context)
  File "C:\Python34\lib\site-packages\django\template\loader_tags.py", line 65, in render
    result = block.nodelist.render(context)
  File "C:\Python34\lib\site-packages\django\template\base.py", line 903, in render
    bit = self.render_node(node, context)
  File "C:\Python34\lib\site-packages\django\template\debug.py", line 79, in render_node
    return node.render(context)
  File "C:\Python34\lib\site-packages\django\template\defaulttags.py", line 507, in render
    six.reraise(*exc_info)
  File "C:\Python34\lib\site-packages\django\utils\six.py", line 659, in reraise
    raise value
  File "C:\Python34\lib\site-packages\django\template\defaulttags.py", line 493, in render
    url = reverse(view_name, args=args, kwargs=kwargs, current_app=current_app)
  File "C:\Python34\lib\site-packages\django\core\urlresolvers.py", line 579, in reverse
    return force_text(iri_to_uri(resolver._reverse_with_prefix(view, prefix, *args, **kwargs)))
  File "C:\Python34\lib\site-packages\django\core\urlresolvers.py", line 496, in _reverse_with_prefix
    (lookup_view_s, args, kwargs, len(patterns), patterns))
django.core.urlresolvers.NoReverseMatch: Reverse for 'labs' with arguments '()' and keyword arguments '{}' not found. 0 pattern(s) tried: []
