[16/Jul/2015 10:01:56] WARNING [django.request:170] Not Found: /apple-touch-icon-precomposed.png
[16/Jul/2015 10:01:56] WARNING [django.request:170] Not Found: /apple-touch-icon.png
[16/Jul/2015 10:02:27] ERROR [django.request:256] Internal Server Error: /open/filter/
Traceback (most recent call last):
  File "/Users/hanschristiangregersen/.virtualenvs/booked/lib/python3.4/site-packages/django/db/backends/utils.py", line 64, in execute
    return self.cursor.execute(sql, params)
  File "/Users/hanschristiangregersen/.virtualenvs/booked/lib/python3.4/site-packages/django/db/backends/sqlite3/base.py", line 318, in execute
    return Database.Cursor.execute(self, query, params)
sqlite3.OperationalError: no such table: pc_computer_labs

The above exception was the direct cause of the following exception:

Traceback (most recent call last):
  File "/Users/hanschristiangregersen/.virtualenvs/booked/lib/python3.4/site-packages/django/core/handlers/base.py", line 132, in get_response
    response = wrapped_callback(request, *callback_args, **callback_kwargs)
  File "/Users/hanschristiangregersen/PycharmProjects/InternProject/pc/views.py", line 57, in filter_suggestions
    data = sorted(data, key=lambda x: x.get_distance(long1=usr_longitude, lat1=usr_latitude))
  File "/Users/hanschristiangregersen/.virtualenvs/booked/lib/python3.4/site-packages/django/db/models/query.py", line 162, in __iter__
    self._fetch_all()
  File "/Users/hanschristiangregersen/.virtualenvs/booked/lib/python3.4/site-packages/django/db/models/query.py", line 965, in _fetch_all
    self._result_cache = list(self.iterator())
  File "/Users/hanschristiangregersen/.virtualenvs/booked/lib/python3.4/site-packages/django/db/models/query.py", line 238, in iterator
    results = compiler.execute_sql()
  File "/Users/hanschristiangregersen/.virtualenvs/booked/lib/python3.4/site-packages/django/db/models/sql/compiler.py", line 840, in execute_sql
    cursor.execute(sql, params)
  File "/Users/hanschristiangregersen/.virtualenvs/booked/lib/python3.4/site-packages/django/db/backends/utils.py", line 79, in execute
    return super(CursorDebugWrapper, self).execute(sql, params)
  File "/Users/hanschristiangregersen/.virtualenvs/booked/lib/python3.4/site-packages/django/db/backends/utils.py", line 64, in execute
    return self.cursor.execute(sql, params)
  File "/Users/hanschristiangregersen/.virtualenvs/booked/lib/python3.4/site-packages/django/db/utils.py", line 97, in __exit__
    six.reraise(dj_exc_type, dj_exc_value, traceback)
  File "/Users/hanschristiangregersen/.virtualenvs/booked/lib/python3.4/site-packages/django/utils/six.py", line 658, in reraise
    raise value.with_traceback(tb)
  File "/Users/hanschristiangregersen/.virtualenvs/booked/lib/python3.4/site-packages/django/db/backends/utils.py", line 64, in execute
    return self.cursor.execute(sql, params)
  File "/Users/hanschristiangregersen/.virtualenvs/booked/lib/python3.4/site-packages/django/db/backends/sqlite3/base.py", line 318, in execute
    return Database.Cursor.execute(self, query, params)
django.db.utils.OperationalError: no such table: pc_computer_labs
[20/Jul/2015 08:55:23] ERROR [django.request:256] Internal Server Error: /like/
Traceback (most recent call last):
  File "/Users/hanschristiangregersen/.virtualenvs/booked/lib/python3.4/site-packages/django/core/handlers/base.py", line 132, in get_response
    response = wrapped_callback(request, *callback_args, **callback_kwargs)
  File "/Users/hanschristiangregersen/PycharmProjects/InternProject/users/views.py", line 130, in like
    user.pc_favourites.get(id=pc_id)
  File "/Users/hanschristiangregersen/.virtualenvs/booked/lib/python3.4/site-packages/django/utils/functional.py", line 227, in inner
    return func(self._wrapped, *args)
AttributeError: 'AnonymousUser' object has no attribute 'pc_favourites'
[20/Jul/2015 08:55:23] ERROR [django.request:256] Internal Server Error: /like/
Traceback (most recent call last):
  File "/Users/hanschristiangregersen/.virtualenvs/booked/lib/python3.4/site-packages/django/core/handlers/base.py", line 132, in get_response
    response = wrapped_callback(request, *callback_args, **callback_kwargs)
  File "/Users/hanschristiangregersen/PycharmProjects/InternProject/users/views.py", line 130, in like
    user.pc_favourites.get(id=pc_id)
  File "/Users/hanschristiangregersen/.virtualenvs/booked/lib/python3.4/site-packages/django/utils/functional.py", line 227, in inner
    return func(self._wrapped, *args)
AttributeError: 'AnonymousUser' object has no attribute 'pc_favourites'
[20/Jul/2015 08:55:24] ERROR [django.request:256] Internal Server Error: /like/
Traceback (most recent call last):
  File "/Users/hanschristiangregersen/.virtualenvs/booked/lib/python3.4/site-packages/django/core/handlers/base.py", line 132, in get_response
    response = wrapped_callback(request, *callback_args, **callback_kwargs)
  File "/Users/hanschristiangregersen/PycharmProjects/InternProject/users/views.py", line 130, in like
    user.pc_favourites.get(id=pc_id)
  File "/Users/hanschristiangregersen/.virtualenvs/booked/lib/python3.4/site-packages/django/utils/functional.py", line 227, in inner
    return func(self._wrapped, *args)
AttributeError: 'AnonymousUser' object has no attribute 'pc_favourites'
[20/Jul/2015 08:55:24] ERROR [django.request:256] Internal Server Error: /like/
Traceback (most recent call last):
  File "/Users/hanschristiangregersen/.virtualenvs/booked/lib/python3.4/site-packages/django/core/handlers/base.py", line 132, in get_response
    response = wrapped_callback(request, *callback_args, **callback_kwargs)
  File "/Users/hanschristiangregersen/PycharmProjects/InternProject/users/views.py", line 130, in like
    user.pc_favourites.get(id=pc_id)
  File "/Users/hanschristiangregersen/.virtualenvs/booked/lib/python3.4/site-packages/django/utils/functional.py", line 227, in inner
    return func(self._wrapped, *args)
AttributeError: 'AnonymousUser' object has no attribute 'pc_favourites'
[20/Jul/2015 08:55:24] ERROR [django.request:256] Internal Server Error: /like/
Traceback (most recent call last):
  File "/Users/hanschristiangregersen/.virtualenvs/booked/lib/python3.4/site-packages/django/core/handlers/base.py", line 132, in get_response
    response = wrapped_callback(request, *callback_args, **callback_kwargs)
  File "/Users/hanschristiangregersen/PycharmProjects/InternProject/users/views.py", line 130, in like
    user.pc_favourites.get(id=pc_id)
  File "/Users/hanschristiangregersen/.virtualenvs/booked/lib/python3.4/site-packages/django/utils/functional.py", line 227, in inner
    return func(self._wrapped, *args)
AttributeError: 'AnonymousUser' object has no attribute 'pc_favourites'
[20/Jul/2015 08:55:24] ERROR [django.request:256] Internal Server Error: /like/
Traceback (most recent call last):
  File "/Users/hanschristiangregersen/.virtualenvs/booked/lib/python3.4/site-packages/django/core/handlers/base.py", line 132, in get_response
    response = wrapped_callback(request, *callback_args, **callback_kwargs)
  File "/Users/hanschristiangregersen/PycharmProjects/InternProject/users/views.py", line 130, in like
    user.pc_favourites.get(id=pc_id)
  File "/Users/hanschristiangregersen/.virtualenvs/booked/lib/python3.4/site-packages/django/utils/functional.py", line 227, in inner
    return func(self._wrapped, *args)
AttributeError: 'AnonymousUser' object has no attribute 'pc_favourites'
