[10/Aug/2015 16:38:20] ERROR [django.request:256] Internal Server Error: /calendar/
Traceback (most recent call last):
  File "/Users/hanschristiangregersen/.virtualenvs/booked/lib/python3.4/site-packages/django/core/handlers/base.py", line 132, in get_response
    response = wrapped_callback(request, *callback_args, **callback_kwargs)
  File "/Users/hanschristiangregersen/PycharmProjects/NewDesignBooked/MyEdProject/users/views.py", line 389, in calendar
    room = Tutorial_Room.objects.get(locationId=locationId)
  File "/Users/hanschristiangregersen/.virtualenvs/booked/lib/python3.4/site-packages/django/db/models/manager.py", line 127, in manager_method
    return getattr(self.get_queryset(), name)(*args, **kwargs)
  File "/Users/hanschristiangregersen/.virtualenvs/booked/lib/python3.4/site-packages/django/db/models/query.py", line 334, in get
    self.model._meta.object_name
rooms.models.DoesNotExist: Tutorial_Room matching query does not exist.
[10/Aug/2015 16:39:14] ERROR [django.request:256] Internal Server Error: /calendar/
Traceback (most recent call last):
  File "/Users/hanschristiangregersen/.virtualenvs/booked/lib/python3.4/site-packages/django/core/handlers/base.py", line 132, in get_response
    response = wrapped_callback(request, *callback_args, **callback_kwargs)
  File "/Users/hanschristiangregersen/PycharmProjects/NewDesignBooked/MyEdProject/users/views.py", line 389, in calendar
    room = Tutorial_Room.objects.get(locationId=locationId)
  File "/Users/hanschristiangregersen/.virtualenvs/booked/lib/python3.4/site-packages/django/db/models/manager.py", line 127, in manager_method
    return getattr(self.get_queryset(), name)(*args, **kwargs)
  File "/Users/hanschristiangregersen/.virtualenvs/booked/lib/python3.4/site-packages/django/db/models/query.py", line 334, in get
    self.model._meta.object_name
rooms.models.DoesNotExist: Tutorial_Room matching query does not exist.
[10/Aug/2015 16:41:43] ERROR [django.request:256] Internal Server Error: /calendar/
Traceback (most recent call last):
  File "/Users/hanschristiangregersen/.virtualenvs/booked/lib/python3.4/site-packages/django/utils/datastructures.py", line 320, in __getitem__
    list_ = super(MultiValueDict, self).__getitem__(key)
KeyError: 'locationId'

During handling of the above exception, another exception occurred:

Traceback (most recent call last):
  File "/Users/hanschristiangregersen/.virtualenvs/booked/lib/python3.4/site-packages/django/core/handlers/base.py", line 132, in get_response
    response = wrapped_callback(request, *callback_args, **callback_kwargs)
  File "/Users/hanschristiangregersen/PycharmProjects/NewDesignBooked/MyEdProject/users/views.py", line 391, in calendar
    locationId = request.POST['locationId']
  File "/Users/hanschristiangregersen/.virtualenvs/booked/lib/python3.4/site-packages/django/utils/datastructures.py", line 322, in __getitem__
    raise MultiValueDictKeyError(repr(key))
django.utils.datastructures.MultiValueDictKeyError: "'locationId'"
[10/Aug/2015 16:42:54] ERROR [django.request:256] Internal Server Error: /calendar/
Traceback (most recent call last):
  File "/Users/hanschristiangregersen/.virtualenvs/booked/lib/python3.4/site-packages/django/utils/datastructures.py", line 320, in __getitem__
    list_ = super(MultiValueDict, self).__getitem__(key)
KeyError: 'locationId'

During handling of the above exception, another exception occurred:

Traceback (most recent call last):
  File "/Users/hanschristiangregersen/.virtualenvs/booked/lib/python3.4/site-packages/django/core/handlers/base.py", line 132, in get_response
    response = wrapped_callback(request, *callback_args, **callback_kwargs)
  File "/Users/hanschristiangregersen/PycharmProjects/NewDesignBooked/MyEdProject/users/views.py", line 391, in calendar
    locationId = request.POST['locationId']
  File "/Users/hanschristiangregersen/.virtualenvs/booked/lib/python3.4/site-packages/django/utils/datastructures.py", line 322, in __getitem__
    raise MultiValueDictKeyError(repr(key))
django.utils.datastructures.MultiValueDictKeyError: "'locationId'"
[10/Aug/2015 16:43:56] ERROR [django.request:256] Internal Server Error: /calendar/
Traceback (most recent call last):
  File "/Users/hanschristiangregersen/.virtualenvs/booked/lib/python3.4/site-packages/django/utils/datastructures.py", line 320, in __getitem__
    list_ = super(MultiValueDict, self).__getitem__(key)
KeyError: 'locationId'

During handling of the above exception, another exception occurred:

Traceback (most recent call last):
  File "/Users/hanschristiangregersen/.virtualenvs/booked/lib/python3.4/site-packages/django/core/handlers/base.py", line 132, in get_response
    response = wrapped_callback(request, *callback_args, **callback_kwargs)
  File "/Users/hanschristiangregersen/PycharmProjects/NewDesignBooked/MyEdProject/users/views.py", line 391, in calendar
    locationId = request.POST['locationId']
  File "/Users/hanschristiangregersen/.virtualenvs/booked/lib/python3.4/site-packages/django/utils/datastructures.py", line 322, in __getitem__
    raise MultiValueDictKeyError(repr(key))
django.utils.datastructures.MultiValueDictKeyError: "'locationId'"
